Workbook

Sheet What to buy 
A1: IBM webMethods Hyb Int Software Sizing Calculator | E1: NOTE: This sheet is only for use with IBM webMethods Hybrid Integration Software Part D11F7ZX
A2: Use this sheet to determine how many RUs are needed for a given configuration
A3: Instructions: enter values in the blue shaded cells
A5: Integration
C6: Year 1 | D6: Year 2 | E6: Year 3 | F6: Year 4 | G6: Year 5
A7: Integration Transactions | B7: Production tx/year
B8: Production tx/month | C8: =ROUND(C7/12,0) -> 0 | D8: =ROUND(D7/12,0) -> 0 | E8: =ROUND(E7/12,0) -> 0 | F8: =ROUND(F7/12,0) -> 0 | G8: =ROUND(G7/12,0) -> 0
B9: Non-production tx/year | C9: =C7/10 -> 0
B10: Non-production tx/month | C10: =ROUND(C9/12,0) -> 0 | D10: =ROUND(D9/12,0) -> 0 | E10: =ROUND(E9/12,0) -> 0 | F10: =ROUND(F9/12,0) -> 0 | G10: =ROUND(G9/12,0) -> 0
A11: RUs | C11: ='Master data'!H5+'Master data'!H10 -> 0 | D11: ='Master data'!I5+'Master data'!I10 -> 0 | E11: ='Master data'!J5+'Master data'!J10 -> 0 | F11: ='Master data'!K5+'Master data'!K10 -> 0 | G11: ='Master data'!L5+'Master data'!L10 -> 0
A13: API Management
C14: Year 1 | D14: Year 2 | E14: Year 3 | F14: Year 4 | G14: Year 5
A15: API Calls | B15: Production tx/year
B16: Production tx/month | C16: =ROUND(C15/12,0) -> 0 | D16: =ROUND(D15/12,0) -> 0 | E16: =ROUND(E15/12,0) -> 0 | F16: =ROUND(F15/12,0) -> 0 | G16: =ROUND(G15/12,0) -> 0
B17: Non-production tx/year | C17: =C15/10 -> 0
B18: Non-production tx/month | C18: =ROUND(C17/12,0) -> 0 | D18: =ROUND(D17/12,0) -> 0 | E18: =ROUND(E17/12,0) -> 0 | F18: =ROUND(F17/12,0) -> 0 | G18: =ROUND(G17/12,0) -> 0
A19: RUs | C19: ='Master data'!H21+'Master data'!H26 -> 0 | D19: ='Master data'!I21+'Master data'!I26 -> 0 | E19: ='Master data'!J21+'Master data'!J26 -> 0 | F19: ='Master data'!K21+'Master data'!K26 -> 0 | G19: ='Master data'!L21+'Master data'!L26 -> 0
A21: B2B
C22: Year 1 | D22: Year 2 | E22: Year 3 | F22: Year 4 | G22: Year 5
A23: B2B Transactions | B23: Production tx/year
B24: Production tx/month | C24: =ROUND(C23/12,0) -> 0 | D24: =ROUND(D23/12,0) -> 0 | E24: =ROUND(E23/12,0) -> 0 | F24: =ROUND(F23/12,0) -> 0 | G24: =ROUND(G23/12,0) -> 0
B25: Non-production tx/year
B26: Non-production tx/month | C26: =ROUND(C25/12,0) -> 0 | D26: =ROUND(D25/12,0) -> 0 | E26: =ROUND(E25/12,0) -> 0 | F26: =ROUND(F25/12,0) -> 0 | G26: =ROUND(G25/12,0) -> 0
A27: RUs | C27: ='Master data'!H37+'Master data'!H42 -> 0 | D27: ='Master data'!I37+'Master data'!I42 -> 0 | E27: ='Master data'!J37+'Master data'!J42 -> 0 | F27: ='Master data'!K37+'Master data'!K42 -> 0 | G27: ='Master data'!L37+'Master data'!L42 -> 0
A29: MFT
C30: Year 1 | D30: Year 2 | E30: Year 3 | F30: Year 4 | G30: Year 5
A31: MFT Transactions | B31: Production tx/year
B32: Production tx/month | C32: =ROUND(C31/12,0) -> 0 | D32: =ROUND(D31/12,0) -> 0 | E32: =ROUND(E31/12,0) -> 0 | F32: =ROUND(F31/12,0) -> 0 | G32: =ROUND(G31/12,0) -> 0
B33: Non-production tx/year | C33: =C31/10 -> 0
B34: Non-production tx/month | C34: =ROUND(C33/12,0) -> 0 | D34: =ROUND(D33/12,0) -> 0 | E34: =ROUND(E33/12,0) -> 0 | F34: =ROUND(F33/12,0) -> 0 | G34: =ROUND(G33/12,0) -> 0
A35: FASP Transactions | B35: Production tx/year
B36: Production tx/month | C36: =ROUND(C35/12,0) -> 0 | D36: =ROUND(D35/12,0) -> 0 | E36: =ROUND(E35/12,0) -> 0 | F36: =ROUND(F35/12,0) -> 0 | G36: =ROUND(G35/12,0) -> 0
B37: Non-production tx/year | C37: =C35/10 -> 0
B38: Non-production tx/month | C38: =ROUND(C37/12,0) -> 0 | D38: =ROUND(D37/12,0) -> 0 | E38: =ROUND(E37/12,0) -> 0 | F38: =ROUND(F37/12,0) -> 0 | G38: =ROUND(G37/12,0) -> 0
A39: RUs | C39: ='Master data'!H53+'Master data'!H58+'Master data'!H65+'Master data'!H70 -> 0 | D39: ='Master data'!I53+'Master data'!I58+'Master data'!I65+'Master data'!I70 -> 0 | E39: ='Master data'!J53+'Master data'!J58+'Master data'!J65+'Master data'!J70 -> 0 | F39: ='Master data'!K53+'Master data'!K58+'Master data'!K65+'Master data'!K70 -> 0 | G39: ='Master data'!L53+'Master data'!L58+'Master data'!L65+'Master data'!L70 -> 0
A41: GraphQL
C42: Year 1 | D42: Year 2 | E42: Year 3 | F42: Year 4 | G42: Year 5
A43: GraphQL Transactions | B43: Production tx/year
B44: Production tx/month | C44: =ROUND(C43/12,0) -> 0 | D44: =ROUND(D43/12,0) -> 0 | E44: =ROUND(E43/12,0) -> 0 | F44: =ROUND(F43/12,0) -> 0 | G44: =ROUND(G43/12,0) -> 0
B45: Non-production tx/year
...

Sheet Metric definitions
A1: B2B
A2: A B2B Transaction is the exchange of any electronic document (e.g., purchase order, purchase order acknowledgment, invoice, ASN) with another entity in any EDI or non-EDI standard format (e.g., EDI, XML, csv). A single document sent or received by the platform is counted as a B2B Transaction. For batch transactions, each single transaction contained within the batch is counted as a B2B Transaction. A document more than 5 kilobytes will be counted as an additional B2B Transaction for each additional 5 kilobytes rounded up to the nearest increment.
A3: For example, a document of 13 kilobytes would count as 3 B2B Transactions.
A4: MFT
A5: A Managed File Transfer (MFT) Transaction is an initiation of an inbound file transfer or an initiation of an outbound file transfer. A file more than 5 megabytes will be counted as an additional MFT Transaction for each additional 5 megabytes rounded up to the nearest increment.
A6: For example, a file of 13 megabytes would count as 3 MFT Transactions.
A7: FASP
A8: A FASP Transaction is an initiation of an inbound file transfer or an initiation of an outbound file transfer. A file more than 5 gigabytes will be counted as an additional FASP Transaction for each additional 5 gigabytes rounded up to the nearest increment.
A9: For example, a file of 13 gigabytes would count as 3 FASP Transactions.
A10: Integration
A11: An Integration Transaction is an execution of a top-level service, flow or workflow that is triggered manually, or by an external event or request, or by a scheduled timer. A service, flow or workflow that takes more than 60 seconds to complete is counted as an additional Integration Transaction for each additional 60 seconds (or part thereof).
A12: For example, a workflow which takes 190 seconds to complete would count as 4 Integration Transactions.
... A25: "Non-Production" means that the Bundled Program can only be deployed as part of Licensee's internal test environment for internal non-production activities.

Sheet Master data
A1: Master data | G1: Calculator
A2: Price per RU | B2: 40
H3: Year 1 | I3: Year 2 | J3: Year 3 | K3: Year 4 | L3: Year 5
A4: Integration | B4: RUs/mth | G4: Qty | H4: ='What to buy '!C7 -> 0 | I4: ='What to buy '!D7 -> 0 | J4: ='What to buy '!E7 -> 0 | K4: ='What to buy '!F7 -> 0 | L4: ='What to buy '!G7 -> 0
B5: From | C5: To | D5: RUs | E5: Per | G5: RUs | H5: =ROUNDUP(MIN(H4,$C6)/$E6,0)*$D6 + IF(H4>$C6,ROUNDUP(MIN(H4-$C6,$C7-$C6)/$E7,0)*$D7,0) + IF(H4>$C7,ROUNDUP(MIN(H4-$C7,$C8-$C7)/$E8,0)*$D8,0) -> 0 | I5: =ROUNDUP(MIN(I4,$C6)/$E6,0)*$D6 + IF(I4>$C6,ROUNDUP(MIN(I4-$C6,$C7-$C6)/$E7,0)*$D7,0) + IF(I4>$C7,ROUNDUP(MIN(I4-$C7,$C8-$C7)/$E8,0)*$D8,0) -> 0 | J5: =ROUNDUP(MIN(J4,$C6)/$E6,0)*$D6 + IF(J4>$C6,ROUNDUP(MIN(J4-$C6,$C7-$C6)/$E7,0)*$D7,0) + IF(J4>$C7,ROUNDUP(MIN(J4-$C7,$C8-$C7)/$E8,0)*$D8,0) -> 0 | K5: =ROUNDUP(MIN(K4,$C6)/$E6,0)*$D6 + IF(K4>$C6,ROUNDUP(MIN(K4-$C6,$C7-$C6)/$E7,0)*$D7,0) + IF(K4>$C7,ROUNDUP(MIN(K4-$C7,$C8-$C7)/$E8,0)*$D8,0) -> 0 | L5: =ROUNDUP(MIN(L4,$C6)/$E6,0)*$D6 + IF(L4>$C6,ROUNDUP(MIN(L4-$C6,$C7-$C6)/$E7,0)*$D7,0) + IF(L4>$C7,ROUNDUP(MIN(L4-$C7,$C8-$C7)/$E8,0)*$D8,0) -> 0
A6: Transactions | B6: 0 | C6: 10000000 | D6: 20 | E6: 100000
B7: =C6+1 -> 10000001 | C7: 100000000 | D7: 4 | E7: =E6 -> 100000
B8: =C7+1 -> 100000001 | C8: 999999999999999 | D8: 1 | E8: =E7 -> 100000
A9: Integration Non-prod | B9: RUs/mth | G9: Qty | H9: ='What to buy '!C9 -> 0 | I9: ='What to buy '!D9 -> 0 | J9: ='What to buy '!E9 -> 0 | K9: ='What to buy '!F9 -> 0 | L9: ='What to buy '!G9 -> 0
B10: From | C10: To | D10: RUs | E10: Per | G10: RUs | H10: =ROUNDUP(MIN(H9,$C11)/$E11,0)*$D11 + IF(H9>$C11,ROUNDUP(MIN(H9-$C11,$C12-$C11)/$E12,0)*$D12,0) + IF(H9>$C12,ROUNDUP(MIN(H9-$C12,$C13-$C12)/$E13,0)*$D13,0) -> 0 | I10: =ROUNDUP(MIN(I9,$C11)/$E11,0)*$D11 + IF(I9>$C11,ROUNDUP(MIN(I9-$C11,$C12-$C11)/$E12,0)*$D12,0) + IF(I9>$C12,ROUNDUP(MIN(I9-$C12,$C13-$C12)/$E13,0)*$D13,0) -> 0 | J10: =ROUNDUP(MIN(J9,$C11)/$E11,0)*$D11 + IF(J9>$C11,ROUNDUP(MIN(J9-$C11,$C12-$C11)/$E12,0)*$D12,0) + IF(J9>$C12,ROUNDUP(MIN(J9-$C12,$C13-$C12)/$E13,0)*$D13,0) -> 0 | K10: =ROUNDUP(MIN(K9,$C11)/$E11,0)*$D11 + IF(K9>$C11,ROUNDUP(MIN(K9-$C11,$C12-$C11)/$E12,0)*$D12,0) + IF(K9>$C12,ROUNDUP(MIN(K9-$C12,$C13-$C12)/$E13,0)*$D13,0) -> 0 | L10: =ROUNDUP(MIN(L9,$C11)/$E11,0)*$D11 + IF(L9>$C11,ROUNDUP(MIN(L9-$C11,$C12-$C11)/$E12,0)*$D12,0) + IF(L9>$C12,ROUNDUP(MIN(L9-$C12,$C13-$C12)/$E13,0)*$D13,0) -> 0
A11: Transactions | B11: 0 | C11: 10000000 | D11: 20 | E11: 200000
B12: =C11+1 -> 10000001 | C12: 100000000 | D12: 4 | E12: 200000
B13: =C12+1 -> 100000001 | C13: 999999999999999 | D13: 1 | E13: 200000
A20: API Management | B20: RUs/mth | G20: Qty | H20: ='What to buy '!C15 -> 0 | I20: ='What to buy '!D15 -> 0 | J20: ='What to buy '!E15 -> 0 | K20: ='What to buy '!F15 -> 0 | L20: ='What to buy '!G15 -> 0
B21: From | C21: To | D21: RUs | E21: Per | G21: RUs | H21: =ROUNDUP(MIN(H20,$C22)/$E22,0)*$D22 + IF(H20>$C22,ROUNDUP(MIN(H20-$C22,$C23-$C22)/$E23,0)*$D23,0) + IF(H20>$C23,ROUNDUP(MIN(H20-$C23,$C24-$C23)/$E24,0)*$D24,0) -> 0 | I21: =ROUNDUP(MIN(I20,$C22)/$E22,0)*$D22 + IF(I20>$C22,ROUNDUP(MIN(I20-$C22,$C23-$C22)/$E23,0)*$D23,0) + IF(I20>$C23,ROUNDUP(MIN(I20-$C23,$C24-$C23)/$E24,0)*$D24,0) -> 0 | J21: =ROUNDUP(MIN(J20,$C22)/$E22,0)*$D22 + IF(J20>$C22,ROUNDUP(MIN(J20-$C22,$C23-$C22)/$E23,0)*$D23,0) + IF(J20>$C23,ROUNDUP(MIN(J20-$C23,$C24-$C23)/$E24,0)*$D24,0) -> 0 | K21: =ROUNDUP(MIN(K20,$C22)/$E22,0)*$D22 + IF(K20>$C22,ROUNDUP(MIN(K20-$C22,$C23-$C22)/$E23,0)*$D23,0) + IF(K20>$C23,ROUNDUP(MIN(K20-$C23,$C24-$C23)/$E24,0)*$D24,0) -> 0 | L21: =ROUNDUP(MIN(L20,$C22)/$E22,0)*$D22 + IF(L20>$C22,ROUNDUP(MIN(L20-$C22,$C23-$C22)/$E23,0)*$D23,0) + IF(L20>$C23,ROUNDUP(MIN(L20-$C23,$C24-$C23)/$E24,0)*$D24,0) -> 0
A22: Transactions | B22: 0 | C22: 100000000 | D22: 20 | E22: 1000000
B23: =C22+1 -> 100000001 | C23: 1000000000 | D23: 3 | E23: =E22 -> 1000000
B24: =C23+1 -> 1000000001 | C24: 999999999999999 | D24: 2 | E24: =E23 -> 1000000
A25: API Management - Non-prod | B25: RUs/mth | G25: Qty | H25: ='What to buy '!C17 -> 0 | I25: ='What to buy '!D17 -> 0 | J25: ='What to buy '!E17 -> 0 | K25: ='What to buy '!F17 -> 0 | L25: ='What to buy '!G17 -> 0
B26: From | C26: To | D26: RUs | E26: Per | G26: RUs | H26: =ROUNDUP(MIN(H25,$C27)/$E27,0)*$D27 + IF(H25>$C27,ROUNDUP(MIN(H25-$C27,$C28-$C27)/$E28,0)*$D28,0) + IF(H25>$C28,ROUNDUP(MIN(H25-$C28,$C29-$C28)/$E29,0)*$D29,0) -> 0 | I26: =ROUNDUP(MIN(I25,$C27)/$E27,0)*$D27 + IF(I25>$C27,ROUNDUP(MIN(I25-$C27,$C28-$C27)/$E28,0)*$D28,0) + IF(I25>$C28,ROUNDUP(MIN(I25-$C28,$C29-$C28)/$E29,0)*$D29,0) -> 0 | J26: =ROUNDUP(MIN(J25,$C27)/$E27,0)*$D27 + IF(J25>$C27,ROUNDUP(MIN(J25-$C27,$C28-$C27)/$E28,0)*$D28,0) + IF(J25>$C28,ROUNDUP(MIN(J25-$C28,$C29-$C28)/$E29,0)*$D29,0) -> 0 | K26: =ROUNDUP(MIN(K25,$C27)/$E27,0)*$D27 + IF(K25>$C27,ROUNDUP(MIN(K25-$C27,$C28-$C27)/$E28,0)*$D28,0) + IF(K25>$C28,ROUNDUP(MIN(K25-$C28,$C29-$C28)/$E29,0)*$D29,0) -> 0 | L26: =ROUNDUP(MIN(L25,$C27)/$E27,0)*$D27 + IF(L25>$C27,ROUNDUP(MIN(L25-$C27,$C28-$C27)/$E28,0)*$D28,0) + IF(L25>$C28,ROUNDUP(MIN(L25-$C28,$C29-$C28)/$E29,0)*$D29,0) -> 0
A27: Transactions | B27: 0 | C27: 100000000 | D27: 20 | E27: 2000000
B28: =C27+1 -> 100000001 | C28: 1000000000 | D28: 3 | E28: =E27 -> 2000000
B29: =C28+1 -> 1000000001 | C29: 999999999999999 | D29: 2 | E29: =E28 -> 2000000
A36: B2B | B36: RUs/mth | G36: Qty | H36: ='What to buy '!C23 -> 0 | I36: ='What to buy '!D23 -> 0 | J36: ='What to buy '!E23 -> 0 | K36: ='What to buy '!F23 -> 0 | L36: ='What to buy '!G23 -> 0
B37: From | C37: To | D37: RUs | E37: Per | G37: RUs | H37: =ROUNDUP(MIN(H36,$C38)/$E38,0)*$D38 + IF(H36>$C38,ROUNDUP(MIN(H36-$C38,$C39-$C38)/$E39,0)*$D39,0) + IF(H36>$C39,ROUNDUP(MIN(H36-$C39,$C40-$C39)/$E40,0)*$D40,0) -> 0 | I37: =ROUNDUP(MIN(I36,$C38)/$E38,0)*$D38 + IF(I36>$C38,ROUNDUP(MIN(I36-$C38,$C39-$C38)/$E39,0)*$D39,0) + IF(I36>$C39,ROUNDUP(MIN(I36-$C39,$C40-$C39)/$E40,0)*$D40,0) -> 0 | J37: =ROUNDUP(MIN(J36,$C38)/$E38,0)*$D38 + IF(J36>$C38,ROUNDUP(MIN(J36-$C38,$C39-$C38)/$E39,0)*$D39,0) + IF(J36>$C39,ROUNDUP(MIN(J36-$C39,$C40-$C39)/$E40,0)*$D40,0) -> 0 | K37: =ROUNDUP(MIN(K36,$C38)/$E38,0)*$D38 + IF(K36>$C38,ROUNDUP(MIN(K36-$C38,$C39-$C38)/$E39,0)*$D39,0) + IF(K36>$C39,ROUNDUP(MIN(K36-$C39,$C40-$C39)/$E40,0)*$D40,0) -> 0 | L37: =ROUNDUP(MIN(L36,$C38)/$E38,0)*$D38 + IF(L36>$C38,ROUNDUP(MIN(L36-$C38,$C39-$C38)/$E39,0)*$D39,0) + IF(L36>$C39,ROUNDUP(MIN(L36-$C39,$C40-$C39)/$E40,0)*$D40,0) -> 0
A38: Transactions | B38: 0 | C38: 10000000 | D38: 20 | E38: 100000
B39: =C38+1 -> 10000001 | C39: 100000000 | D39: 4 | E39: =E38 -> 100000
B40: =C39+1 -> 100000001 | C40: 999999999999999 | D40: 1 | E40: =E39 -> 100000
A41: B2B - Non-Prod | B41: RUs/mth | G41: Qty | H41: ='What to buy '!C25 -> 0 | I41: ='What to buy '!D25 -> 0 | J41: ='What to buy '!E25 -> 0 | K41: ='What to buy '!F25 -> 0 | L41: ='What to buy '!G25 -> 0
B42: From | C42: To | D42: RUs | E42: Per | G42: RUs | H42: =ROUNDUP(MIN(H41,$C43)/$E43,0)*$D43 + IF(H41>$C43,ROUNDUP(MIN(H41-$C43,$C44-$C43)/$E44,0)*$D44,0) + IF(H41>$C44,ROUNDUP(MIN(H41-$C44,$C45-$C44)/$E45,0)*$D45,0) -> 0 | I42: =ROUNDUP(MIN(I41,$C43)/$E43,0)*$D43 + IF(I41>$C43,ROUNDUP(MIN(I41-$C43,$C44-$C43)/$E44,0)*$D44,0) + IF(I41>$C44,ROUNDUP(MIN(I41-$C44,$C45-$C44)/$E45,0)*$D45,0) -> 0 | J42: =ROUNDUP(MIN(J41,$C43)/$E43,0)*$D43 + IF(J41>$C43,ROUNDUP(MIN(J41-$C43,$C44-$C43)/$E44,0)*$D44,0) + IF(J41>$C44,ROUNDUP(MIN(J41-$C44,$C45-$C44)/$E45,0)*$D45,0) -> 0 | K42: =ROUNDUP(MIN(K41,$C43)/$E43,0)*$D43 + IF(K41>$C43,ROUNDUP(MIN(K41-$C43,$C44-$C43)/$E44,0)*$D44,0) + IF(K41>$C44,ROUNDUP(MIN(K41-$C44,$C45-$C44)/$E45,0)*$D45,0) -> 0 | L42: =ROUNDUP(MIN(L41,$C43)/$E43,0)*$D43 + IF(L41>$C43,ROUNDUP(MIN(L41-$C43,$C44-$C43)/$E44,0)*$D44,0) + IF(L41>$C44,ROUNDUP(MIN(L41-$C44,$C45-$C44)/$E45,0)*$D45,0) -> 0
A43: Transactions | B43: 0 | C43: 10000000 | D43: 20 | E43: 200000
B44: =C43+1 -> 10000001 | C44: 100000000 | D44: 4 | E44: =E43 -> 200000
B45: =C44+1 -> 100000001 | C45: 999999999999999 | D45: 1 | E45: =E44 -> 200000
A52: MFT | B52: RUs/mth | G52: Qty | H52: ='What to buy '!C31 -> 0 | I52: ='What to buy '!D31 -> 0 | J52: ='What to buy '!E31 -> 0 | K52: ='What to buy '!F31 -> 0 | L52: ='What to buy '!G31 -> 0
B53: From | C53: To | D53: RUs | E53: Per | G53: RUs | H53: =ROUNDUP(MIN(H52,$C54)/$E54,0)*$D54 + IF(H52>$C54,ROUNDUP(MIN(H52-$C54,$C55-$C54)/$E55,0)*$D55,0) + IF(H52>$C55,ROUNDUP(MIN(H52-$C55,$C56-$C55)/$E56,0)*$D56,0) -> 0 | I53: =ROUNDUP(MIN(I52,$C54)/$E54,0)*$D54 + IF(I52>$C54,ROUNDUP(MIN(I52-$C54,$C55-$C54)/$E55,0)*$D55,0) + IF(I52>$C55,ROUNDUP(MIN(I52-$C55,$C56-$C55)/$E56,0)*$D56,0) -> 0 | J53: =ROUNDUP(MIN(J52,$C54)/$E54,0)*$D54 + IF(J52>$C54,ROUNDUP(MIN(J52-$C54,$C55-$C54)/$E55,0)*$D55,0) + IF(J52>$C55,ROUNDUP(MIN(J52-$C55,$C56-$C55)/$E56,0)*$D56,0) -> 0 | K53: =ROUNDUP(MIN(K52,$C54)/$E54,0)*$D54 + IF(K52>$C54,ROUNDUP(MIN(K52-$C54,$C55-$C54)/$E55,0)*$D55,0) + IF(K52>$C55,ROUNDUP(MIN(K52-$C55,$C56-$C55)/$E56,0)*$D56,0) -> 0 | L53: =ROUNDUP(MIN(L52,$C54)/$E54,0)*$D54 + IF(L52>$C54,ROUNDUP(MIN(L52-$C54,$C55-$C54)/$E55,0)*$D55,0) + IF(L52>$C55,ROUNDUP(MIN(L52-$C55,$C56-$C55)/$E56,0)*$D56,0) -> 0
A54: Transactions | B54: 0 | C54: 10000000 | D54: 20 | E54: 100000
B55: =C54+1 -> 10000001 | C55: 100000000 | D55: 4 | E55: =E54 -> 100000
B56: =C55+1 -> 100000001 | C56: 999999999999999 | D56: 1 | E56: =E55 -> 100000
A57: MFT-non-prod | B57: RUs/mth | G57: Qty | H57: ='What to buy '!C33 -> 0 | I57: ='What to buy '!D33 -> 0 | J57: ='What to buy '!E33 -> 0 | K57: ='What to buy '!F33 -> 0 | L57: ='What to buy '!G33 -> 0
B58: From | C58: To | D58: RUs | E58: Per | G58: RUs | H58: =ROUNDUP(MIN(H57,$C59)/$E59,0)*$D59 + IF(H57>$C59,ROUNDUP(MIN(H57-$C59,$C60-$C59)/$E60,0)*$D60,0) + IF(H57>$C60,ROUNDUP(MIN(H57-$C60,$C61-$C60)/$E61,0)*$D61,0) -> 0 | I58: =ROUNDUP(MIN(I57,$C59)/$E59,0)*$D59 + IF(I57>$C59,ROUNDUP(MIN(I57-$C59,$C60-$C59)/$E60,0)*$D60,0) + IF(I57>$C60,ROUNDUP(MIN(I57-$C60,$C61-$C60)/$E61,0)*$D61,0) -> 0 | J58: =ROUNDUP(MIN(J57,$C59)/$E59,0)*$D59 + IF(J57>$C59,ROUNDUP(MIN(J57-$C59,$C60-$C59)/$E60,0)*$D60,0) + IF(J57>$C60,ROUNDUP(MIN(J57-$C60,$C61-$C60)/$E61,0)*$D61,0) -> 0 | K58: =ROUNDUP(MIN(K57,$C59)/$E59,0)*$D59 + IF(K57>$C59,ROUNDUP(MIN(K57-$C59,$C60-$C59)/$E60,0)*$D60,0) + IF(K57>$C60,ROUNDUP(MIN(K57-$C60,$C61-$C60)/$E61,0)*$D61,0) -> 0 | L58: =ROUNDUP(MIN(L57,$C59)/$E59,0)*$D59 + IF(L57>$C59,ROUNDUP(MIN(L57-$C59,$C60-$C59)/$E60,0)*$D60,0) + IF(L57>$C60,ROUNDUP(MIN(L57-$C60,$C61-$C60)/$E61,0)*$D61,0) -> 0
...
