Workbook

Sheet What to buy 
A1: IBM webMethods Hyb Int SaaS Sizing Calculator | E1: NOTE: This sheet is only for use with IBM webMethodsHybrid Integration SaaS Part D0YG9ZX
A2: Use this sheet to determine how many RUs are needed for a given configuration
A3: Instructions: enter values in the blue shaded cells
A5: Integration
C6: Year 1 | D6: Year 2 | E6: Year 3 | F6: Year 4 | G6: Year 5 | H6: Private Network Connection
A7: Development environment | B7: # months | H7: FALSE
A8: Test environment | B8: # months | H8: FALSE
A9: Production environment | B9: # months | H9: FALSE
A10: Additional environments | B10: # Count of envirnoment | H10: FALSE
B11: # Avg. months active
A12: Additional runtimes | B12: # runtimes (12mth)
A13: Integration Transactions | B13: Production tx/year
B14: Production tx/month | C14: =ROUND(C13/12,0) -> 0 | D14: =ROUND(D13/12,0) -> 0 | E14: =ROUND(E13/12,0) -> 0 | F14: =ROUND(F13/12,0) -> 0 | G14: =ROUND(G13/12,0) -> 0
B15: Non-production tx/year | C15: =C13/10 -> 0
B16: Non-production tx/month | C16: =ROUND(C15/12,0) -> 0 | D16: =ROUND(D15/12,0) -> 0 | E16: =ROUND(E15/12,0) -> 0 | F16: =ROUND(F15/12,0) -> 0 | G16: =ROUND(G15/12,0) -> 0
A17: RUs | C17: =((C7+C8+C9+C10*C11)*'Master data'!$B5)+(C12*'Master data'!$B$6*12)+'Master data'!H5+'Master data'!H11 -> 0 | D17: =((D7+D8+D9+D10*D11)*'Master data'!$B5)+(D12*'Master data'!$B$6*12)+'Master data'!I5+'Master data'!I11 -> 0 | E17: =((E7+E8+E9+E10*E11)*'Master data'!$B5)+(E12*'Master data'!$B$6*12)+'Master data'!J5+'Master data'!J11 -> 0 | F17: =((F7+F8+F9+F10*F11)*'Master data'!$B5)+(F12*'Master data'!$B$6*12)+'Master data'!K5+'Master data'!K11 -> 0 | G17: =((G7+G8+G9+G10*G11)*'Master data'!$B5)+(G12*'Master data'!$B$6*12)+'Master data'!L5+'Master data'!L11 -> 0
A19: API Management
C20: Year 1 | D20: Year 2 | E20: Year 3 | F20: Year 4 | G20: Year 5 | H20: Private Network Connection
A21: Development environment | B21: # months | H21: FALSE
A22: Test environment | B22: # months | H22: FALSE
A23: Production environment | B23: # months | H23: FALSE
A24: Additional environments | B24: # Count of envirnoment | H24: FALSE
B25: # Avg. months active
A26: API Calls | B26: Production tx/year
B27: Production tx/month | C27: =ROUND(C26/12,0) -> 0 | D27: =ROUND(D26/12,0) -> 0 | E27: =ROUND(E26/12,0) -> 0 | F27: =ROUND(F26/12,0) -> 0 | G27: =ROUND(G26/12,0) -> 0
B28: Non-production tx/year | C28: =C26/10 -> 0 | D28: =D26/5 -> 0 | E28: =E26/5 -> 0
B29: Non-production tx/month | C29: =ROUND(C28/12,0) -> 0 | D29: =ROUND(D28/12,0) -> 0 | E29: =ROUND(E28/12,0) -> 0 | F29: =ROUND(F28/12,0) -> 0 | G29: =ROUND(G28/12,0) -> 0
A30: RUs | C30: =((C21+C22+C23+C24*C25)*'Master data'!$B22)+'Master data'!H22+'Master data'!H27 -> 0 | D30: =((D21+D22+D23+D24*D25)*'Master data'!$B22)+'Master data'!I22+'Master data'!I27 -> 0 | E30: =((E21+E22+E23+E24*E25)*'Master data'!$B22)+'Master data'!J22+'Master data'!J27 -> 0 | F30: =((F21+F22+F23+F24*F25)*'Master data'!$B22)+'Master data'!K22+'Master data'!K27 -> 0 | G30: =((G21+G22+G23+G24*G25)*'Master data'!$B22)+'Master data'!L22+'Master data'!L27 -> 0
A32: B2B
C33: Year 1 | D33: Year 2 | E33: Year 3 | F33: Year 4 | G33: Year 5 | H33: Private Network Connection
A34: Development environment | B34: # months | H34: FALSE
A35: Test environment | B35: # months | H35: FALSE
A36: Production environment | B36: # months | H36: FALSE
A37: Additional environments | B37: # Count of envirnoment | H37: FALSE
B38: # Avg. months active
A39: B2B Transactions | B39: Production tx/year
B40: Production tx/month | C40: =ROUND(C39/12,0) -> 0 | D40: =ROUND(D39/12,0) -> 0 | E40: =ROUND(E39/12,0) -> 0 | F40: =ROUND(F39/12,0) -> 0 | G40: =ROUND(G39/12,0) -> 0
B41: Non-production tx/year | C41: =C39/10 -> 0
B42: Non-production tx/month | C42: =ROUND(C41/12,0) -> 0 | D42: =ROUND(D41/12,0) -> 0 | E42: =ROUND(E41/12,0) -> 0 | F42: =ROUND(F41/12,0) -> 0 | G42: =ROUND(G41/12,0) -> 0
A43: VAN Transactions | B43: Production tx/year
...

Sheet Master data
A1: Master data | G1: Calculator
A2: Price per RU | B2: 40.08
H3: Year 1 | I3: Year 2 | J3: Year 3 | K3: Year 4 | L3: Year 5
A4: Integration | B4: RUs/mth | G4: Qty | H4: ='What to buy '!C13 -> 0 | I4: ='What to buy '!D13 -> 0 | J4: ='What to buy '!E13 -> 0 | K4: ='What to buy '!F13 -> 0 | L4: ='What to buy '!G13 -> 0
A5: Environment | B5: 60 | G5: RUs | H5: =ROUNDUP(IF(H4>$C8,$C8,H4)/$E8,0)*$D8+ROUNDUP(IF(H4>$C8,H4-$C8,0)/$E9,0)*$D9 -> 0 | I5: =ROUNDUP(IF(I4>$C8,$C8,I4)/$E8,0)*$D8+ROUNDUP(IF(I4>$C8,I4-$C8,0)/$E9,0)*$D9 -> 0 | J5: =ROUNDUP(IF(J4>$C8,$C8,J4)/$E8,0)*$D8+ROUNDUP(IF(J4>$C8,J4-$C8,0)/$E9,0)*$D9 -> 0 | K5: =ROUNDUP(IF(K4>$C8,$C8,K4)/$E8,0)*$D8+ROUNDUP(IF(K4>$C8,K4-$C8,0)/$E9,0)*$D9 -> 0 | L5: =ROUNDUP(IF(L4>$C8,$C8,L4)/$E8,0)*$D8+ROUNDUP(IF(L4>$C8,L4-$C8,0)/$E9,0)*$D9 -> 0
A6: Runtime | B6: 5
B7: From | C7: To | D7: RUs | E7: Per
A8: Transactions | B8: 0 | C8: 100000000 | D8: 4 | E8: 100000
B9: =C8+1 -> 100000001 | C9: 999999999999 | D9: 1 | E9: =E8 -> 100000
A10: Integration - non-prod | B10: RUs/mth | G10: Qty | H10: ='What to buy '!C15 -> 0 | I10: ='What to buy '!D15 -> 0 | J10: ='What to buy '!E15 -> 0 | K10: ='What to buy '!F15 -> 0 | L10: ='What to buy '!G15 -> 0
G11: RUs | H11: =ROUNDUP(IF(H10>$C14,$C14,H10)/$E14,0)*$D14+ROUNDUP(IF(H10>$C14,H10-$C14,0)/$E15,0)*$D15 -> 0 | I11: =ROUNDUP(IF(I10>$C14,$C14,I10)/$E14,0)*$D14+ROUNDUP(IF(I10>$C14,I10-$C14,0)/$E15,0)*$D15 -> 0 | J11: =ROUNDUP(IF(J10>$C14,$C14,J10)/$E14,0)*$D14+ROUNDUP(IF(J10>$C14,J10-$C14,0)/$E15,0)*$D15 -> 0 | K11: =ROUNDUP(IF(K10>$C14,$C14,K10)/$E14,0)*$D14+ROUNDUP(IF(K10>$C14,K10-$C14,0)/$E15,0)*$D15 -> 0 | L11: =ROUNDUP(IF(L10>$C14,$C14,L10)/$E14,0)*$D14+ROUNDUP(IF(L10>$C14,L10-$C14,0)/$E15,0)*$D15 -> 0
B13: From | C13: To | D13: RUs | E13: Per
A14: Transactions | B14: 0 | C14: 100000000 | D14: 4 | E14: 200000
B15: =C14+1 -> 100000001 | C15: 999999999999 | D15: 1 | E15: =E14 -> 200000
A21: API Management | B21: RUs/mth | G21: Qty | H21: ='What to buy '!C26 -> 0 | I21: ='What to buy '!D26 -> 0 | J21: ='What to buy '!E26 -> 0 | K21: ='What to buy '!F26 -> 0 | L21: ='What to buy '!G26 -> 0
A22: Environment | B22: 50 | G22: RUs | H22: =ROUNDUP(IF(H21>$C24,$C24,H21)/$E24,0)*$D24+ROUNDUP(IF(H21>$C24,H21-$C24,0)/$E25,0)*$D25 -> 0 | I22: =ROUNDUP(IF(I21>$C24,$C24,I21)/$E24,0)*$D24+ROUNDUP(IF(I21>$C24,I21-$C24,0)/$E25,0)*$D25 -> 0 | J22: =ROUNDUP(IF(J21>$C24,$C24,J21)/$E24,0)*$D24+ROUNDUP(IF(J21>$C24,J21-$C24,0)/$E25,0)*$D25 -> 0 | K22: =ROUNDUP(IF(K21>$C24,$C24,K21)/$E24,0)*$D24+ROUNDUP(IF(K21>$C24,K21-$C24,0)/$E25,0)*$D25 -> 0 | L22: =ROUNDUP(IF(L21>$C24,$C24,L21)/$E24,0)*$D24+ROUNDUP(IF(L21>$C24,L21-$C24,0)/$E25,0)*$D25 -> 0
B23: From | C23: To | D23: RUs | E23: Per
A24: Transactions | B24: 0 | C24: 1000000000 | D24: 3 | E24: 1000000
B25: =C24+1 -> 1000000001 | C25: 999999999999 | D25: 2 | E25: =E24 -> 1000000
A26: API Management - non-prod | B26: RUs/mth | G26: Qty | H26: ='What to buy '!C28 -> 0 | I26: ='What to buy '!D28 -> 0 | J26: ='What to buy '!E28 -> 0 | K26: ='What to buy '!F28 -> 0 | L26: ='What to buy '!G28 -> 0
G27: RUs | H27: =ROUNDUP(IF(H26>$C29,$C29,H26)/$E29,0)*$D29+ROUNDUP(IF(H26>$C29,H26-$C29,0)/$E30,0)*$D30 -> 0 | I27: =ROUNDUP(IF(I26>$C29,$C29,I26)/$E29,0)*$D29+ROUNDUP(IF(I26>$C29,I26-$C29,0)/$E30,0)*$D30 -> 0 | J27: =ROUNDUP(IF(J26>$C29,$C29,J26)/$E29,0)*$D29+ROUNDUP(IF(J26>$C29,J26-$C29,0)/$E30,0)*$D30 -> 0 | K27: =ROUNDUP(IF(K26>$C29,$C29,K26)/$E29,0)*$D29+ROUNDUP(IF(K26>$C29,K26-$C29,0)/$E30,0)*$D30 -> 0 | L27: =ROUNDUP(IF(L26>$C29,$C29,L26)/$E29,0)*$D29+ROUNDUP(IF(L26>$C29,L26-$C29,0)/$E30,0)*$D30 -> 0
B28: From | C28: To | D28: RUs | E28: Per
A29: Transactions | B29: 0 | C29: 1000000000 | D29: 3 | E29: 2000000
B30: =C29+1 -> 1000000001 | C30: 999999999999 | D30: 2 | E30: =E29 -> 2000000
A36: B2B | B36: RUs/mth | G36: Qty | H36: ='What to buy '!C39 -> 0 | I36: ='What to buy '!D39 -> 0 | J36: ='What to buy '!E39 -> 0 | K36: ='What to buy '!F39 -> 0 | L36: ='What to buy '!G39 -> 0
A37: Environment | B37: 60 | G37: RUs | H37: =ROUNDUP(IF(H36>$C39,$C39,H36)/$E39,0)*$D39+ROUNDUP(IF(H36>$C39,H36-$C39,0)/$E40,0)*$D40 -> 0 | I37: =ROUNDUP(IF(I36>$C39,$C39,I36)/$E39,0)*$D39+ROUNDUP(IF(I36>$C39,I36-$C39,0)/$E40,0)*$D40 -> 0 | J37: =ROUNDUP(IF(J36>$C39,$C39,J36)/$E39,0)*$D39+ROUNDUP(IF(J36>$C39,J36-$C39,0)/$E40,0)*$D40 -> 0 | K37: =ROUNDUP(IF(K36>$C39,$C39,K36)/$E39,0)*$D39+ROUNDUP(IF(K36>$C39,K36-$C39,0)/$E40,0)*$D40 -> 0 | L37: =ROUNDUP(IF(L36>$C39,$C39,L36)/$E39,0)*$D39+ROUNDUP(IF(L36>$C39,L36-$C39,0)/$E40,0)*$D40 -> 0
B38: From | C38: To | D38: RUs | E38: Per
A39: Transactions | B39: 0 | C39: 100000000 | D39: 4 | E39: 100000
B40: =C39+1 -> 100000001 | C40: 999999999999 | D40: 1 | E40: =E39 -> 100000
A41: B2B - non-prod | B41: RUs/mth | G41: Qty | H41: ='What to buy '!C41 -> 0 | I41: ='What to buy '!D41 -> 0 | J41: ='What to buy '!E41 -> 0 | K41: ='What to buy '!F41 -> 0 | L41: ='What to buy '!G41 -> 0
G42: RUs | H42: =ROUNDUP(IF(H41>$C44,$C44,H41)/$E44,0)*$D44+ROUNDUP(IF(H41>$C44,H41-$C44,0)/$E45,0)*$D45 -> 0 | I42: =ROUNDUP(IF(I41>$C44,$C44,I41)/$E44,0)*$D44+ROUNDUP(IF(I41>$C44,I41-$C44,0)/$E45,0)*$D45 -> 0 | J42: =ROUNDUP(IF(J41>$C44,$C44,J41)/$E44,0)*$D44+ROUNDUP(IF(J41>$C44,J41-$C44,0)/$E45,0)*$D45 -> 0 | K42: =ROUNDUP(IF(K41>$C44,$C44,K41)/$E44,0)*$D44+ROUNDUP(IF(K41>$C44,K41-$C44,0)/$E45,0)*$D45 -> 0 | L42: =ROUNDUP(IF(L41>$C44,$C44,L41)/$E44,0)*$D44+ROUNDUP(IF(L41>$C44,L41-$C44,0)/$E45,0)*$D45 -> 0
B43: From | C43: To | D43: RUs | E43: Per
A44: Transactions | B44: 0 | C44: 100000000 | D44: 4 | E44: 200000
B45: =C44+1 -> 100000001 | C45: 999999999999 | D45: 1 | E45: =E44 -> 200000
A48: VAN | B48: RUs/mth | G48: Qty | H48: ='What to buy '!C43 -> 0 | I48: ='What to buy '!D43 -> 0 | J48: ='What to buy '!E43 -> 0 | K48: ='What to buy '!F43 -> 0 | L48: ='What to buy '!G43 -> 0
A49: Environment | B49: N/A | G49: RUs | H49: =ROUNDUP(IF(H48>$C51,$C51,H48)/$E51,0)*$D51+ROUNDUP(IF(H48>$C51,H48-$C51,0)/$E52,0)*$D52 -> 0 | I49: =ROUNDUP(IF(I48>$C51,$C51,I48)/$E51,0)*$D51+ROUNDUP(IF(I48>$C51,I48-$C51,0)/$E52,0)*$D52 -> 0 | J49: =ROUNDUP(IF(J48>$C51,$C51,J48)/$E51,0)*$D51+ROUNDUP(IF(J48>$C51,J48-$C51,0)/$E52,0)*$D52 -> 0 | K49: =ROUNDUP(IF(K48>$C51,$C51,K48)/$E51,0)*$D51+ROUNDUP(IF(K48>$C51,K48-$C51,0)/$E52,0)*$D52 -> 0 | L49: =ROUNDUP(IF(L48>$C51,$C51,L48)/$E51,0)*$D51+ROUNDUP(IF(L48>$C51,L48-$C51,0)/$E52,0)*$D52 -> 0
B50: From | C50: To | D50: RUs | E50: Per
A51: Transactions | B51: 0 | C51: 1000000 | D51: 30 | E51: 10000
B52: =C51+1 -> 1000001 | C52: 999999999999 | D52: 10 | E52: =E51 -> 10000
A53: VAN - non-prod | B53: RUs/mth | G53: Qty | H53: ='What to buy '!C45 -> 0 | I53: ='What to buy '!D45 -> 0 | J53: ='What to buy '!E45 -> 0 | K53: ='What to buy '!F45 -> 0 | L53: ='What to buy '!G45 -> 0
...
